cuda
current epoch is 0
current batch is 0
0.9976695775985718
Traceback (most recent call last):
  File "/home/baebro/landmark_extraction/model/train.py", line 102, in <module>
    for batch_idx, (anchor, pos, neg) in enumerate(train_dataloader):
  File "/home/baebro/anaconda3/envs/mp/lib/python3.10/site-packages/torch/utils/data/dataloader.py", line 701, in __next__
    data = self._next_data()
  File "/home/baebro/anaconda3/envs/mp/lib/python3.10/site-packages/torch/utils/data/dataloader.py", line 1445, in _next_data
    return self._process_data(data)
  File "/home/baebro/anaconda3/envs/mp/lib/python3.10/site-packages/torch/utils/data/dataloader.py", line 1491, in _process_data
    data.reraise()
  File "/home/baebro/anaconda3/envs/mp/lib/python3.10/site-packages/torch/_utils.py", line 715, in reraise
    raise exception
RuntimeError: Caught RuntimeError in DataLoader worker process 1.
Original Traceback (most recent call last):
  File "/home/baebro/anaconda3/envs/mp/lib/python3.10/site-packages/torch/utils/data/_utils/worker.py", line 351, in _worker_loop
    data = fetcher.fetch(index)  # type: ignore[possibly-undefined]
  File "/home/baebro/anaconda3/envs/mp/lib/python3.10/site-packages/torch/utils/data/_utils/fetch.py", line 55, in fetch
    return self.collate_fn(data)
  File "/home/baebro/anaconda3/envs/mp/lib/python3.10/site-packages/torch/utils/data/_utils/collate.py", line 398, in default_collate
    return collate(batch, collate_fn_map=default_collate_fn_map)
  File "/home/baebro/anaconda3/envs/mp/lib/python3.10/site-packages/torch/utils/data/_utils/collate.py", line 211, in collate
    return [
  File "/home/baebro/anaconda3/envs/mp/lib/python3.10/site-packages/torch/utils/data/_utils/collate.py", line 212, in <listcomp>
    collate(samples, collate_fn_map=collate_fn_map)
  File "/home/baebro/anaconda3/envs/mp/lib/python3.10/site-packages/torch/utils/data/_utils/collate.py", line 155, in collate
    return collate_fn_map[elem_type](batch, collate_fn_map=collate_fn_map)
  File "/home/baebro/anaconda3/envs/mp/lib/python3.10/site-packages/torch/utils/data/_utils/collate.py", line 271, in collate_tensor_fn
    out = elem.new(storage).resize_(len(batch), *list(elem.size()))
RuntimeError: Trying to resize storage that is not resizable
